06/30/2022 04:50:27 PM : loginauth.logger : 
Traceback (most recent call last):
  File "/home/ushkamalla/PycharmProjects/loginregDjango/FundooNotes/loginauth/views.py", line 373, in post
    serializer.is_valid(raise_exception=True)
  File "/home/ushkamalla/PycharmProjects/loginregDjango/FundooNotes/venv/lib/python3.8/site-packages/rest_framework/serializers.py", line 235, in is_valid
    raise ValidationError(self.errors)
rest_framework.exceptions.ValidationError: {'first_name': [ErrorDetail(string='This field is required.', code='required')], 'last_name': [ErrorDetail(string='This field is required.', code='required')], 'email': [ErrorDetail(string='This field is required.', code='required')], 'username': [ErrorDetail(string='This field is required.', code='required')], 'password': [ErrorDetail(string='This field is required.', code='required')]}
06/30/2022 04:50:27 PM : loginauth.logger : 
Traceback (most recent call last):
  File "/home/ushkamalla/PycharmProjects/loginregDjango/FundooNotes/loginauth/views.py", line 373, in post
    serializer.is_valid(raise_exception=True)
  File "/home/ushkamalla/PycharmProjects/loginregDjango/FundooNotes/venv/lib/python3.8/site-packages/rest_framework/serializers.py", line 235, in is_valid
    raise ValidationError(self.errors)
rest_framework.exceptions.ValidationError: {'first_name': [ErrorDetail(string='This field is required.', code='required')], 'last_name': [ErrorDetail(string='This field is required.', code='required')], 'email': [ErrorDetail(string='This field is required.', code='required')], 'username': [ErrorDetail(string='This field is required.', code='required')], 'password': [ErrorDetail(string='This field is required.', code='required')]}
06/30/2022 04:53:07 PM : loginauth.logger : 
Traceback (most recent call last):
  File "/home/ushkamalla/PycharmProjects/loginregDjango/FundooNotes/loginauth/views.py", line 373, in post
    serializer.is_valid(raise_exception=True)
  File "/home/ushkamalla/PycharmProjects/loginregDjango/FundooNotes/venv/lib/python3.8/site-packages/rest_framework/serializers.py", line 235, in is_valid
    raise ValidationError(self.errors)
rest_framework.exceptions.ValidationError: {'first_name': [ErrorDetail(string='Ensure this field has at least 2 characters.', code='min_length')], 'last_name': [ErrorDetail(string='Ensure this field has at least 2 characters.', code='min_length')]}
06/30/2022 04:53:07 PM : loginauth.logger : 
Traceback (most recent call last):
  File "/home/ushkamalla/PycharmProjects/loginregDjango/FundooNotes/loginauth/views.py", line 373, in post
    serializer.is_valid(raise_exception=True)
  File "/home/ushkamalla/PycharmProjects/loginregDjango/FundooNotes/venv/lib/python3.8/site-packages/rest_framework/serializers.py", line 235, in is_valid
    raise ValidationError(self.errors)
rest_framework.exceptions.ValidationError: {'first_name': [ErrorDetail(string='Ensure this field has at least 2 characters.', code='min_length')], 'last_name': [ErrorDetail(string='Ensure this field has at least 2 characters.', code='min_length')]}
06/30/2022 04:55:13 PM : loginauth.logger : 
Traceback (most recent call last):
  File "/home/ushkamalla/PycharmProjects/loginregDjango/FundooNotes/loginauth/views.py", line 323, in post
    serializer.is_valid(raise_exception=True)
  File "/home/ushkamalla/PycharmProjects/loginregDjango/FundooNotes/venv/lib/python3.8/site-packages/rest_framework/serializers.py", line 235, in is_valid
    raise ValidationError(self.errors)
rest_framework.exceptions.ValidationError: {'username': [ErrorDetail(string='This field is required.', code='required')], 'password': [ErrorDetail(string='This field is required.', code='required')]}
06/30/2022 04:55:13 PM : loginauth.logger : 
Traceback (most recent call last):
  File "/home/ushkamalla/PycharmProjects/loginregDjango/FundooNotes/loginauth/views.py", line 323, in post
    serializer.is_valid(raise_exception=True)
  File "/home/ushkamalla/PycharmProjects/loginregDjango/FundooNotes/venv/lib/python3.8/site-packages/rest_framework/serializers.py", line 235, in is_valid
    raise ValidationError(self.errors)
rest_framework.exceptions.ValidationError: {'username': [ErrorDetail(string='This field is required.', code='required')], 'password': [ErrorDetail(string='This field is required.', code='required')]}
06/30/2022 06:29:59 PM : loginauth.logger : 
Traceback (most recent call last):
  File "/home/ushkamalla/PycharmProjects/loginregDjango/FundooNotes/loginauth/views.py", line 323, in post
    serializer.is_valid(raise_exception=True)
  File "/home/ushkamalla/PycharmProjects/loginregDjango/FundooNotes/venv/lib/python3.8/site-packages/rest_framework/serializers.py", line 235, in is_valid
    raise ValidationError(self.errors)
rest_framework.exceptions.ValidationError: {'username': [ErrorDetail(string='This field is required.', code='required')], 'password': [ErrorDetail(string='This field is required.', code='required')]}
06/30/2022 06:29:59 PM : loginauth.logger : 
Traceback (most recent call last):
  File "/home/ushkamalla/PycharmProjects/loginregDjango/FundooNotes/loginauth/views.py", line 323, in post
    serializer.is_valid(raise_exception=True)
  File "/home/ushkamalla/PycharmProjects/loginregDjango/FundooNotes/venv/lib/python3.8/site-packages/rest_framework/serializers.py", line 235, in is_valid
    raise ValidationError(self.errors)
rest_framework.exceptions.ValidationError: {'username': [ErrorDetail(string='This field is required.', code='required')], 'password': [ErrorDetail(string='This field is required.', code='required')]}
06/30/2022 06:36:05 PM : loginauth.logger : 
Traceback (most recent call last):
  File "/home/ushkamalla/PycharmProjects/loginregDjango/FundooNotes/loginauth/views.py", line 428, in put
    serializer.is_valid(raise_exception=True)
  File "/home/ushkamalla/PycharmProjects/loginregDjango/FundooNotes/venv/lib/python3.8/site-packages/rest_framework/serializers.py", line 235, in is_valid
    raise ValidationError(self.errors)
rest_framework.exceptions.ValidationError: {'username': [ErrorDetail(string='This field is required.', code='required')]}
06/30/2022 06:36:05 PM : loginauth.logger : 
Traceback (most recent call last):
  File "/home/ushkamalla/PycharmProjects/loginregDjango/FundooNotes/loginauth/views.py", line 428, in put
    serializer.is_valid(raise_exception=True)
  File "/home/ushkamalla/PycharmProjects/loginregDjango/FundooNotes/venv/lib/python3.8/site-packages/rest_framework/serializers.py", line 235, in is_valid
    raise ValidationError(self.errors)
rest_framework.exceptions.ValidationError: {'username': [ErrorDetail(string='This field is required.', code='required')]}
06/30/2022 06:36:49 PM : loginauth.logger : 
Traceback (most recent call last):
  File "/home/ushkamalla/PycharmProjects/loginregDjango/FundooNotes/loginauth/utils.py", line 17, in get_object_by_id
    return User.objects.get(id=id)
  File "/home/ushkamalla/PycharmProjects/loginregDjango/FundooNotes/venv/lib/python3.8/site-packages/django/db/models/manager.py", line 85, in manager_method
    return getattr(self.get_queryset(), name)(*args, **kwargs)
  File "/home/ushkamalla/PycharmProjects/loginregDjango/FundooNotes/venv/lib/python3.8/site-packages/django/db/models/query.py", line 496, in get
    raise self.model.DoesNotExist(
django.contrib.auth.models.User.DoesNotExist: User matching query does not exist.
06/30/2022 06:36:49 PM : loginauth.logger : 
Traceback (most recent call last):
  File "/home/ushkamalla/PycharmProjects/loginregDjango/FundooNotes/loginauth/utils.py", line 17, in get_object_by_id
    return User.objects.get(id=id)
  File "/home/ushkamalla/PycharmProjects/loginregDjango/FundooNotes/venv/lib/python3.8/site-packages/django/db/models/manager.py", line 85, in manager_method
    return getattr(self.get_queryset(), name)(*args, **kwargs)
  File "/home/ushkamalla/PycharmProjects/loginregDjango/FundooNotes/venv/lib/python3.8/site-packages/django/db/models/query.py", line 496, in get
    raise self.model.DoesNotExist(
django.contrib.auth.models.User.DoesNotExist: User matching query does not exist.
06/30/2022 06:36:49 PM : loginauth.logger : 
Traceback (most recent call last):
  File "/home/ushkamalla/PycharmProjects/loginregDjango/FundooNotes/loginauth/utils.py", line 17, in get_object_by_id
    return User.objects.get(id=id)
  File "/home/ushkamalla/PycharmProjects/loginregDjango/FundooNotes/venv/lib/python3.8/site-packages/django/db/models/manager.py", line 85, in manager_method
    return getattr(self.get_queryset(), name)(*args, **kwargs)
  File "/home/ushkamalla/PycharmProjects/loginregDjango/FundooNotes/venv/lib/python3.8/site-packages/django/db/models/query.py", line 496, in get
    raise self.model.DoesNotExist(
django.contrib.auth.models.User.DoesNotExist: User matching query does not exist.

During handling of the above exception, another exception occurred:

Traceback (most recent call last):
  File "/home/ushkamalla/PycharmProjects/loginregDjango/FundooNotes/loginauth/views.py", line 430, in put
    user = get_object_by_id(request.data.get('id'))
  File "/home/ushkamalla/PycharmProjects/loginregDjango/FundooNotes/loginauth/utils.py", line 20, in get_object_by_id
    raise User.DoesNotExist
django.contrib.auth.models.User.DoesNotExist
06/30/2022 06:36:49 PM : loginauth.logger : 
Traceback (most recent call last):
  File "/home/ushkamalla/PycharmProjects/loginregDjango/FundooNotes/loginauth/utils.py", line 17, in get_object_by_id
    return User.objects.get(id=id)
  File "/home/ushkamalla/PycharmProjects/loginregDjango/FundooNotes/venv/lib/python3.8/site-packages/django/db/models/manager.py", line 85, in manager_method
    return getattr(self.get_queryset(), name)(*args, **kwargs)
  File "/home/ushkamalla/PycharmProjects/loginregDjango/FundooNotes/venv/lib/python3.8/site-packages/django/db/models/query.py", line 496, in get
    raise self.model.DoesNotExist(
django.contrib.auth.models.User.DoesNotExist: User matching query does not exist.

During handling of the above exception, another exception occurred:

Traceback (most recent call last):
  File "/home/ushkamalla/PycharmProjects/loginregDjango/FundooNotes/loginauth/views.py", line 430, in put
    user = get_object_by_id(request.data.get('id'))
  File "/home/ushkamalla/PycharmProjects/loginregDjango/FundooNotes/loginauth/utils.py", line 20, in get_object_by_id
    raise User.DoesNotExist
django.contrib.auth.models.User.DoesNotExist
06/30/2022 06:37:12 PM : loginauth.logger : 
Traceback (most recent call last):
  File "/home/ushkamalla/PycharmProjects/loginregDjango/FundooNotes/loginauth/utils.py", line 17, in get_object_by_id
    return User.objects.get(id=id)
  File "/home/ushkamalla/PycharmProjects/loginregDjango/FundooNotes/venv/lib/python3.8/site-packages/django/db/models/manager.py", line 85, in manager_method
    return getattr(self.get_queryset(), name)(*args, **kwargs)
  File "/home/ushkamalla/PycharmProjects/loginregDjango/FundooNotes/venv/lib/python3.8/site-packages/django/db/models/query.py", line 496, in get
    raise self.model.DoesNotExist(
django.contrib.auth.models.User.DoesNotExist: User matching query does not exist.
06/30/2022 06:37:12 PM : loginauth.logger : 
Traceback (most recent call last):
  File "/home/ushkamalla/PycharmProjects/loginregDjango/FundooNotes/loginauth/utils.py", line 17, in get_object_by_id
    return User.objects.get(id=id)
  File "/home/ushkamalla/PycharmProjects/loginregDjango/FundooNotes/venv/lib/python3.8/site-packages/django/db/models/manager.py", line 85, in manager_method
    return getattr(self.get_queryset(), name)(*args, **kwargs)
  File "/home/ushkamalla/PycharmProjects/loginregDjango/FundooNotes/venv/lib/python3.8/site-packages/django/db/models/query.py", line 496, in get
    raise self.model.DoesNotExist(
django.contrib.auth.models.User.DoesNotExist: User matching query does not exist.
06/30/2022 06:37:12 PM : loginauth.logger : 
Traceback (most recent call last):
  File "/home/ushkamalla/PycharmProjects/loginregDjango/FundooNotes/loginauth/utils.py", line 17, in get_object_by_id
    return User.objects.get(id=id)
  File "/home/ushkamalla/PycharmProjects/loginregDjango/FundooNotes/venv/lib/python3.8/site-packages/django/db/models/manager.py", line 85, in manager_method
    return getattr(self.get_queryset(), name)(*args, **kwargs)
  File "/home/ushkamalla/PycharmProjects/loginregDjango/FundooNotes/venv/lib/python3.8/site-packages/django/db/models/query.py", line 496, in get
    raise self.model.DoesNotExist(
django.contrib.auth.models.User.DoesNotExist: User matching query does not exist.

During handling of the above exception, another exception occurred:

Traceback (most recent call last):
  File "/home/ushkamalla/PycharmProjects/loginregDjango/FundooNotes/loginauth/views.py", line 430, in put
    user = get_object_by_id(request.data.get('id'))
  File "/home/ushkamalla/PycharmProjects/loginregDjango/FundooNotes/loginauth/utils.py", line 20, in get_object_by_id
    raise User.DoesNotExist
django.contrib.auth.models.User.DoesNotExist
06/30/2022 06:37:12 PM : loginauth.logger : 
Traceback (most recent call last):
  File "/home/ushkamalla/PycharmProjects/loginregDjango/FundooNotes/loginauth/utils.py", line 17, in get_object_by_id
    return User.objects.get(id=id)
  File "/home/ushkamalla/PycharmProjects/loginregDjango/FundooNotes/venv/lib/python3.8/site-packages/django/db/models/manager.py", line 85, in manager_method
    return getattr(self.get_queryset(), name)(*args, **kwargs)
  File "/home/ushkamalla/PycharmProjects/loginregDjango/FundooNotes/venv/lib/python3.8/site-packages/django/db/models/query.py", line 496, in get
    raise self.model.DoesNotExist(
django.contrib.auth.models.User.DoesNotExist: User matching query does not exist.

During handling of the above exception, another exception occurred:

Traceback (most recent call last):
  File "/home/ushkamalla/PycharmProjects/loginregDjango/FundooNotes/loginauth/views.py", line 430, in put
    user = get_object_by_id(request.data.get('id'))
  File "/home/ushkamalla/PycharmProjects/loginregDjango/FundooNotes/loginauth/utils.py", line 20, in get_object_by_id
    raise User.DoesNotExist
django.contrib.auth.models.User.DoesNotExist
06/30/2022 06:39:56 PM : loginauth.logger : 
Traceback (most recent call last):
  File "/home/ushkamalla/PycharmProjects/loginregDjango/FundooNotes/venv/lib/python3.8/site-packages/rest_framework/parsers.py", line 65, in parse
    return json.load(decoded_stream, parse_constant=parse_constant)
  File "/home/ushkamalla/PycharmProjects/loginregDjango/FundooNotes/venv/lib/python3.8/site-packages/rest_framework/utils/json.py", line 31, in load
    return json.load(*args, **kwargs)
  File "/usr/lib/python3.8/json/__init__.py", line 293, in load
    return loads(fp.read(),
  File "/usr/lib/python3.8/json/__init__.py", line 370, in loads
    return cls(**kw).decode(s)
  File "/usr/lib/python3.8/json/decoder.py", line 337, in decode
    obj, end = self.raw_decode(s, idx=_w(s, 0).end())
  File "/usr/lib/python3.8/json/decoder.py", line 353, in raw_decode
    obj, end = self.scan_once(s, idx)
json.decoder.JSONDecodeError: Expecting property name enclosed in double quotes: line 5 column 1 (char 42)

During handling of the above exception, another exception occurred:

Traceback (most recent call last):
  File "/home/ushkamalla/PycharmProjects/loginregDjango/FundooNotes/loginauth/views.py", line 427, in put
    serializer = UsernameSerializer(data=request.data)
  File "/home/ushkamalla/PycharmProjects/loginregDjango/FundooNotes/venv/lib/python3.8/site-packages/rest_framework/request.py", line 216, in data
    self._load_data_and_files()
  File "/home/ushkamalla/PycharmProjects/loginregDjango/FundooNotes/venv/lib/python3.8/site-packages/rest_framework/request.py", line 279, in _load_data_and_files
    self._data, self._files = self._parse()
  File "/home/ushkamalla/PycharmProjects/loginregDjango/FundooNotes/venv/lib/python3.8/site-packages/rest_framework/request.py", line 354, in _parse
    parsed = parser.parse(stream, media_type, self.parser_context)
  File "/home/ushkamalla/PycharmProjects/loginregDjango/FundooNotes/venv/lib/python3.8/site-packages/rest_framework/parsers.py", line 67, in parse
    raise ParseError('JSON parse error - %s' % str(exc))
rest_framework.exceptions.ParseError: JSON parse error - Expecting property name enclosed in double quotes: line 5 column 1 (char 42)
06/30/2022 06:39:56 PM : loginauth.logger : 
Traceback (most recent call last):
  File "/home/ushkamalla/PycharmProjects/loginregDjango/FundooNotes/venv/lib/python3.8/site-packages/rest_framework/parsers.py", line 65, in parse
    return json.load(decoded_stream, parse_constant=parse_constant)
  File "/home/ushkamalla/PycharmProjects/loginregDjango/FundooNotes/venv/lib/python3.8/site-packages/rest_framework/utils/json.py", line 31, in load
    return json.load(*args, **kwargs)
  File "/usr/lib/python3.8/json/__init__.py", line 293, in load
    return loads(fp.read(),
  File "/usr/lib/python3.8/json/__init__.py", line 370, in loads
    return cls(**kw).decode(s)
  File "/usr/lib/python3.8/json/decoder.py", line 337, in decode
    obj, end = self.raw_decode(s, idx=_w(s, 0).end())
  File "/usr/lib/python3.8/json/decoder.py", line 353, in raw_decode
    obj, end = self.scan_once(s, idx)
json.decoder.JSONDecodeError: Expecting property name enclosed in double quotes: line 5 column 1 (char 42)

During handling of the above exception, another exception occurred:

Traceback (most recent call last):
  File "/home/ushkamalla/PycharmProjects/loginregDjango/FundooNotes/loginauth/views.py", line 427, in put
    serializer = UsernameSerializer(data=request.data)
  File "/home/ushkamalla/PycharmProjects/loginregDjango/FundooNotes/venv/lib/python3.8/site-packages/rest_framework/request.py", line 216, in data
    self._load_data_and_files()
  File "/home/ushkamalla/PycharmProjects/loginregDjango/FundooNotes/venv/lib/python3.8/site-packages/rest_framework/request.py", line 279, in _load_data_and_files
    self._data, self._files = self._parse()
  File "/home/ushkamalla/PycharmProjects/loginregDjango/FundooNotes/venv/lib/python3.8/site-packages/rest_framework/request.py", line 354, in _parse
    parsed = parser.parse(stream, media_type, self.parser_context)
  File "/home/ushkamalla/PycharmProjects/loginregDjango/FundooNotes/venv/lib/python3.8/site-packages/rest_framework/parsers.py", line 67, in parse
    raise ParseError('JSON parse error - %s' % str(exc))
rest_framework.exceptions.ParseError: JSON parse error - Expecting property name enclosed in double quotes: line 5 column 1 (char 42)
06/30/2022 06:40:38 PM : loginauth.logger : 
Traceback (most recent call last):
  File "/home/ushkamalla/PycharmProjects/loginregDjango/FundooNotes/loginauth/utils.py", line 17, in get_object_by_id
    return User.objects.get(id=id)
  File "/home/ushkamalla/PycharmProjects/loginregDjango/FundooNotes/venv/lib/python3.8/site-packages/django/db/models/manager.py", line 85, in manager_method
    return getattr(self.get_queryset(), name)(*args, **kwargs)
  File "/home/ushkamalla/PycharmProjects/loginregDjango/FundooNotes/venv/lib/python3.8/site-packages/django/db/models/query.py", line 496, in get
    raise self.model.DoesNotExist(
django.contrib.auth.models.User.DoesNotExist: User matching query does not exist.
06/30/2022 06:40:38 PM : loginauth.logger : 
Traceback (most recent call last):
  File "/home/ushkamalla/PycharmProjects/loginregDjango/FundooNotes/loginauth/utils.py", line 17, in get_object_by_id
    return User.objects.get(id=id)
  File "/home/ushkamalla/PycharmProjects/loginregDjango/FundooNotes/venv/lib/python3.8/site-packages/django/db/models/manager.py", line 85, in manager_method
    return getattr(self.get_queryset(), name)(*args, **kwargs)
  File "/home/ushkamalla/PycharmProjects/loginregDjango/FundooNotes/venv/lib/python3.8/site-packages/django/db/models/query.py", line 496, in get
    raise self.model.DoesNotExist(
django.contrib.auth.models.User.DoesNotExist: User matching query does not exist.
06/30/2022 06:40:38 PM : loginauth.logger : 
Traceback (most recent call last):
  File "/home/ushkamalla/PycharmProjects/loginregDjango/FundooNotes/loginauth/utils.py", line 17, in get_object_by_id
    return User.objects.get(id=id)
  File "/home/ushkamalla/PycharmProjects/loginregDjango/FundooNotes/venv/lib/python3.8/site-packages/django/db/models/manager.py", line 85, in manager_method
    return getattr(self.get_queryset(), name)(*args, **kwargs)
  File "/home/ushkamalla/PycharmProjects/loginregDjango/FundooNotes/venv/lib/python3.8/site-packages/django/db/models/query.py", line 496, in get
    raise self.model.DoesNotExist(
django.contrib.auth.models.User.DoesNotExist: User matching query does not exist.

During handling of the above exception, another exception occurred:

Traceback (most recent call last):
  File "/home/ushkamalla/PycharmProjects/loginregDjango/FundooNotes/loginauth/views.py", line 430, in put
    user = get_object_by_id(request.data.get('id'))
  File "/home/ushkamalla/PycharmProjects/loginregDjango/FundooNotes/loginauth/utils.py", line 20, in get_object_by_id
    raise User.DoesNotExist
django.contrib.auth.models.User.DoesNotExist
06/30/2022 06:40:38 PM : loginauth.logger : 
Traceback (most recent call last):
  File "/home/ushkamalla/PycharmProjects/loginregDjango/FundooNotes/loginauth/utils.py", line 17, in get_object_by_id
    return User.objects.get(id=id)
  File "/home/ushkamalla/PycharmProjects/loginregDjango/FundooNotes/venv/lib/python3.8/site-packages/django/db/models/manager.py", line 85, in manager_method
    return getattr(self.get_queryset(), name)(*args, **kwargs)
  File "/home/ushkamalla/PycharmProjects/loginregDjango/FundooNotes/venv/lib/python3.8/site-packages/django/db/models/query.py", line 496, in get
    raise self.model.DoesNotExist(
django.contrib.auth.models.User.DoesNotExist: User matching query does not exist.

During handling of the above exception, another exception occurred:

Traceback (most recent call last):
  File "/home/ushkamalla/PycharmProjects/loginregDjango/FundooNotes/loginauth/views.py", line 430, in put
    user = get_object_by_id(request.data.get('id'))
  File "/home/ushkamalla/PycharmProjects/loginregDjango/FundooNotes/loginauth/utils.py", line 20, in get_object_by_id
    raise User.DoesNotExist
django.contrib.auth.models.User.DoesNotExist
06/30/2022 06:40:54 PM : loginauth.logger : 
Traceback (most recent call last):
  File "/home/ushkamalla/PycharmProjects/loginregDjango/FundooNotes/loginauth/utils.py", line 17, in get_object_by_id
    return User.objects.get(id=id)
  File "/home/ushkamalla/PycharmProjects/loginregDjango/FundooNotes/venv/lib/python3.8/site-packages/django/db/models/manager.py", line 85, in manager_method
    return getattr(self.get_queryset(), name)(*args, **kwargs)
  File "/home/ushkamalla/PycharmProjects/loginregDjango/FundooNotes/venv/lib/python3.8/site-packages/django/db/models/query.py", line 496, in get
    raise self.model.DoesNotExist(
django.contrib.auth.models.User.DoesNotExist: User matching query does not exist.
06/30/2022 06:40:54 PM : loginauth.logger : 
Traceback (most recent call last):
  File "/home/ushkamalla/PycharmProjects/loginregDjango/FundooNotes/loginauth/utils.py", line 17, in get_object_by_id
    return User.objects.get(id=id)
  File "/home/ushkamalla/PycharmProjects/loginregDjango/FundooNotes/venv/lib/python3.8/site-packages/django/db/models/manager.py", line 85, in manager_method
    return getattr(self.get_queryset(), name)(*args, **kwargs)
  File "/home/ushkamalla/PycharmProjects/loginregDjango/FundooNotes/venv/lib/python3.8/site-packages/django/db/models/query.py", line 496, in get
    raise self.model.DoesNotExist(
django.contrib.auth.models.User.DoesNotExist: User matching query does not exist.
06/30/2022 06:40:54 PM : loginauth.logger : 
Traceback (most recent call last):
  File "/home/ushkamalla/PycharmProjects/loginregDjango/FundooNotes/loginauth/utils.py", line 17, in get_object_by_id
    return User.objects.get(id=id)
  File "/home/ushkamalla/PycharmProjects/loginregDjango/FundooNotes/venv/lib/python3.8/site-packages/django/db/models/manager.py", line 85, in manager_method
    return getattr(self.get_queryset(), name)(*args, **kwargs)
  File "/home/ushkamalla/PycharmProjects/loginregDjango/FundooNotes/venv/lib/python3.8/site-packages/django/db/models/query.py", line 496, in get
    raise self.model.DoesNotExist(
django.contrib.auth.models.User.DoesNotExist: User matching query does not exist.

During handling of the above exception, another exception occurred:

Traceback (most recent call last):
  File "/home/ushkamalla/PycharmProjects/loginregDjango/FundooNotes/loginauth/views.py", line 430, in put
    user = get_object_by_id(request.data.get('id'))
  File "/home/ushkamalla/PycharmProjects/loginregDjango/FundooNotes/loginauth/utils.py", line 20, in get_object_by_id
    raise User.DoesNotExist
django.contrib.auth.models.User.DoesNotExist
06/30/2022 06:40:54 PM : loginauth.logger : 
Traceback (most recent call last):
  File "/home/ushkamalla/PycharmProjects/loginregDjango/FundooNotes/loginauth/utils.py", line 17, in get_object_by_id
    return User.objects.get(id=id)
  File "/home/ushkamalla/PycharmProjects/loginregDjango/FundooNotes/venv/lib/python3.8/site-packages/django/db/models/manager.py", line 85, in manager_method
    return getattr(self.get_queryset(), name)(*args, **kwargs)
  File "/home/ushkamalla/PycharmProjects/loginregDjango/FundooNotes/venv/lib/python3.8/site-packages/django/db/models/query.py", line 496, in get
    raise self.model.DoesNotExist(
django.contrib.auth.models.User.DoesNotExist: User matching query does not exist.

During handling of the above exception, another exception occurred:

Traceback (most recent call last):
  File "/home/ushkamalla/PycharmProjects/loginregDjango/FundooNotes/loginauth/views.py", line 430, in put
    user = get_object_by_id(request.data.get('id'))
  File "/home/ushkamalla/PycharmProjects/loginregDjango/FundooNotes/loginauth/utils.py", line 20, in get_object_by_id
    raise User.DoesNotExist
django.contrib.auth.models.User.DoesNotExist
06/30/2022 06:41:17 PM : loginauth.logger : 
Traceback (most recent call last):
  File "/home/ushkamalla/PycharmProjects/loginregDjango/FundooNotes/loginauth/utils.py", line 17, in get_object_by_id
    return User.objects.get(id=id)
  File "/home/ushkamalla/PycharmProjects/loginregDjango/FundooNotes/venv/lib/python3.8/site-packages/django/db/models/manager.py", line 85, in manager_method
    return getattr(self.get_queryset(), name)(*args, **kwargs)
  File "/home/ushkamalla/PycharmProjects/loginregDjango/FundooNotes/venv/lib/python3.8/site-packages/django/db/models/query.py", line 496, in get
    raise self.model.DoesNotExist(
django.contrib.auth.models.User.DoesNotExist: User matching query does not exist.
06/30/2022 06:41:17 PM : loginauth.logger : 
Traceback (most recent call last):
  File "/home/ushkamalla/PycharmProjects/loginregDjango/FundooNotes/loginauth/utils.py", line 17, in get_object_by_id
    return User.objects.get(id=id)
  File "/home/ushkamalla/PycharmProjects/loginregDjango/FundooNotes/venv/lib/python3.8/site-packages/django/db/models/manager.py", line 85, in manager_method
    return getattr(self.get_queryset(), name)(*args, **kwargs)
  File "/home/ushkamalla/PycharmProjects/loginregDjango/FundooNotes/venv/lib/python3.8/site-packages/django/db/models/query.py", line 496, in get
    raise self.model.DoesNotExist(
django.contrib.auth.models.User.DoesNotExist: User matching query does not exist.
06/30/2022 06:41:17 PM : loginauth.logger : 
Traceback (most recent call last):
  File "/home/ushkamalla/PycharmProjects/loginregDjango/FundooNotes/loginauth/utils.py", line 17, in get_object_by_id
    return User.objects.get(id=id)
  File "/home/ushkamalla/PycharmProjects/loginregDjango/FundooNotes/venv/lib/python3.8/site-packages/django/db/models/manager.py", line 85, in manager_method
    return getattr(self.get_queryset(), name)(*args, **kwargs)
  File "/home/ushkamalla/PycharmProjects/loginregDjango/FundooNotes/venv/lib/python3.8/site-packages/django/db/models/query.py", line 496, in get
    raise self.model.DoesNotExist(
django.contrib.auth.models.User.DoesNotExist: User matching query does not exist.

During handling of the above exception, another exception occurred:

Traceback (most recent call last):
  File "/home/ushkamalla/PycharmProjects/loginregDjango/FundooNotes/loginauth/views.py", line 430, in put
    user = get_object_by_id(request.data.get('id'))
  File "/home/ushkamalla/PycharmProjects/loginregDjango/FundooNotes/loginauth/utils.py", line 20, in get_object_by_id
    raise User.DoesNotExist
django.contrib.auth.models.User.DoesNotExist
06/30/2022 06:41:17 PM : loginauth.logger : 
Traceback (most recent call last):
  File "/home/ushkamalla/PycharmProjects/loginregDjango/FundooNotes/loginauth/utils.py", line 17, in get_object_by_id
    return User.objects.get(id=id)
  File "/home/ushkamalla/PycharmProjects/loginregDjango/FundooNotes/venv/lib/python3.8/site-packages/django/db/models/manager.py", line 85, in manager_method
    return getattr(self.get_queryset(), name)(*args, **kwargs)
  File "/home/ushkamalla/PycharmProjects/loginregDjango/FundooNotes/venv/lib/python3.8/site-packages/django/db/models/query.py", line 496, in get
    raise self.model.DoesNotExist(
django.contrib.auth.models.User.DoesNotExist: User matching query does not exist.

During handling of the above exception, another exception occurred:

Traceback (most recent call last):
  File "/home/ushkamalla/PycharmProjects/loginregDjango/FundooNotes/loginauth/views.py", line 430, in put
    user = get_object_by_id(request.data.get('id'))
  File "/home/ushkamalla/PycharmProjects/loginregDjango/FundooNotes/loginauth/utils.py", line 20, in get_object_by_id
    raise User.DoesNotExist
django.contrib.auth.models.User.DoesNotExist
06/30/2022 06:41:24 PM : loginauth.logger : 
Traceback (most recent call last):
  File "/home/ushkamalla/PycharmProjects/loginregDjango/FundooNotes/loginauth/utils.py", line 17, in get_object_by_id
    return User.objects.get(id=id)
  File "/home/ushkamalla/PycharmProjects/loginregDjango/FundooNotes/venv/lib/python3.8/site-packages/django/db/models/manager.py", line 85, in manager_method
    return getattr(self.get_queryset(), name)(*args, **kwargs)
  File "/home/ushkamalla/PycharmProjects/loginregDjango/FundooNotes/venv/lib/python3.8/site-packages/django/db/models/query.py", line 496, in get
    raise self.model.DoesNotExist(
django.contrib.auth.models.User.DoesNotExist: User matching query does not exist.
06/30/2022 06:41:24 PM : loginauth.logger : 
Traceback (most recent call last):
  File "/home/ushkamalla/PycharmProjects/loginregDjango/FundooNotes/loginauth/utils.py", line 17, in get_object_by_id
    return User.objects.get(id=id)
  File "/home/ushkamalla/PycharmProjects/loginregDjango/FundooNotes/venv/lib/python3.8/site-packages/django/db/models/manager.py", line 85, in manager_method
    return getattr(self.get_queryset(), name)(*args, **kwargs)
  File "/home/ushkamalla/PycharmProjects/loginregDjango/FundooNotes/venv/lib/python3.8/site-packages/django/db/models/query.py", line 496, in get
    raise self.model.DoesNotExist(
django.contrib.auth.models.User.DoesNotExist: User matching query does not exist.
06/30/2022 06:41:24 PM : loginauth.logger : 
Traceback (most recent call last):
  File "/home/ushkamalla/PycharmProjects/loginregDjango/FundooNotes/loginauth/utils.py", line 17, in get_object_by_id
    return User.objects.get(id=id)
  File "/home/ushkamalla/PycharmProjects/loginregDjango/FundooNotes/venv/lib/python3.8/site-packages/django/db/models/manager.py", line 85, in manager_method
    return getattr(self.get_queryset(), name)(*args, **kwargs)
  File "/home/ushkamalla/PycharmProjects/loginregDjango/FundooNotes/venv/lib/python3.8/site-packages/django/db/models/query.py", line 496, in get
    raise self.model.DoesNotExist(
django.contrib.auth.models.User.DoesNotExist: User matching query does not exist.

During handling of the above exception, another exception occurred:

Traceback (most recent call last):
  File "/home/ushkamalla/PycharmProjects/loginregDjango/FundooNotes/loginauth/views.py", line 430, in put
    user = get_object_by_id(request.data.get('id'))
  File "/home/ushkamalla/PycharmProjects/loginregDjango/FundooNotes/loginauth/utils.py", line 20, in get_object_by_id
    raise User.DoesNotExist
django.contrib.auth.models.User.DoesNotExist
06/30/2022 06:41:24 PM : loginauth.logger : 
Traceback (most recent call last):
  File "/home/ushkamalla/PycharmProjects/loginregDjango/FundooNotes/loginauth/utils.py", line 17, in get_object_by_id
    return User.objects.get(id=id)
  File "/home/ushkamalla/PycharmProjects/loginregDjango/FundooNotes/venv/lib/python3.8/site-packages/django/db/models/manager.py", line 85, in manager_method
    return getattr(self.get_queryset(), name)(*args, **kwargs)
  File "/home/ushkamalla/PycharmProjects/loginregDjango/FundooNotes/venv/lib/python3.8/site-packages/django/db/models/query.py", line 496, in get
    raise self.model.DoesNotExist(
django.contrib.auth.models.User.DoesNotExist: User matching query does not exist.

During handling of the above exception, another exception occurred:

Traceback (most recent call last):
  File "/home/ushkamalla/PycharmProjects/loginregDjango/FundooNotes/loginauth/views.py", line 430, in put
    user = get_object_by_id(request.data.get('id'))
  File "/home/ushkamalla/PycharmProjects/loginregDjango/FundooNotes/loginauth/utils.py", line 20, in get_object_by_id
    raise User.DoesNotExist
django.contrib.auth.models.User.DoesNotExist
06/30/2022 06:43:42 PM : loginauth.logger : 
Traceback (most recent call last):
  File "/home/ushkamalla/PycharmProjects/loginregDjango/FundooNotes/loginauth/views.py", line 471, in put
    serializer.is_valid(raise_exception=True)
  File "/home/ushkamalla/PycharmProjects/loginregDjango/FundooNotes/venv/lib/python3.8/site-packages/rest_framework/serializers.py", line 235, in is_valid
    raise ValidationError(self.errors)
rest_framework.exceptions.ValidationError: {'username': [ErrorDetail(string='This field is required.', code='required')], 'password': [ErrorDetail(string='This field is required.', code='required')]}
06/30/2022 06:43:42 PM : loginauth.logger : 
Traceback (most recent call last):
  File "/home/ushkamalla/PycharmProjects/loginregDjango/FundooNotes/loginauth/views.py", line 471, in put
    serializer.is_valid(raise_exception=True)
  File "/home/ushkamalla/PycharmProjects/loginregDjango/FundooNotes/venv/lib/python3.8/site-packages/rest_framework/serializers.py", line 235, in is_valid
    raise ValidationError(self.errors)
rest_framework.exceptions.ValidationError: {'username': [ErrorDetail(string='This field is required.', code='required')], 'password': [ErrorDetail(string='This field is required.', code='required')]}
06/30/2022 06:44:32 PM : loginauth.logger : 
Traceback (most recent call last):
  File "/home/ushkamalla/PycharmProjects/loginregDjango/FundooNotes/loginauth/views.py", line 323, in post
    serializer.is_valid(raise_exception=True)
  File "/home/ushkamalla/PycharmProjects/loginregDjango/FundooNotes/venv/lib/python3.8/site-packages/rest_framework/serializers.py", line 235, in is_valid
    raise ValidationError(self.errors)
rest_framework.exceptions.ValidationError: {'username': [ErrorDetail(string='This field is required.', code='required')], 'password': [ErrorDetail(string='This field is required.', code='required')]}
06/30/2022 06:44:32 PM : loginauth.logger : 
Traceback (most recent call last):
  File "/home/ushkamalla/PycharmProjects/loginregDjango/FundooNotes/loginauth/views.py", line 323, in post
    serializer.is_valid(raise_exception=True)
  File "/home/ushkamalla/PycharmProjects/loginregDjango/FundooNotes/venv/lib/python3.8/site-packages/rest_framework/serializers.py", line 235, in is_valid
    raise ValidationError(self.errors)
rest_framework.exceptions.ValidationError: {'username': [ErrorDetail(string='This field is required.', code='required')], 'password': [ErrorDetail(string='This field is required.', code='required')]}
06/30/2022 06:47:15 PM : loginauth.logger : 
Traceback (most recent call last):
  File "/home/ushkamalla/PycharmProjects/loginregDjango/FundooNotes/loginauth/views.py", line 542, in get
    token = kwargs['token']
KeyError: 'token'
06/30/2022 06:47:15 PM : loginauth.logger : 
Traceback (most recent call last):
  File "/home/ushkamalla/PycharmProjects/loginregDjango/FundooNotes/loginauth/views.py", line 542, in get
    token = kwargs['token']
KeyError: 'token'
